Workbook

Sheet 요약
A1: 오성철강 2025년 9월 ~ 2026년 8월 (1년) 실적 요약
A2: 매출: 그린ERP 작업실적(발생주의) + 스크랩(고철) 매출 / 비용: 하나·우리은행 실제 출금(현금주의, 대표자 관련 특수항목 제외) — 스크랩 현금분(노란 셀)은 미확인 가정치입니다.
A4: 매출 합계 (그린ERP 1년 작업실적) | B4: =매출_ERP!B18 -> 673459335
A5: 스크랩(고철) 매출 - 은행입금 실제 | B5: =매출_스크랩!B18 -> 147824150
A6: 스크랩(고철) 매출 - 통장 외 현금 (가정, 월 400만원) | B6: =매출_스크랩!C18 -> 48000000
A7: 총매출 (ERP + 스크랩 은행 + 스크랩 현금가정) | B7: =B4+B5+B6 -> 869283485
A8: 영업비용 합계 (은행 출금, 대표자 특수항목 제외) | B8: =비용_요약!B34 -> 896166180
A9: 영업손익 추정치 (총매출 - 비용, 스크랩 포함) | B9: =B7-B8 -> -26882695
A10: 참고: 스크랩 매출 미포함 시 손익 | B10: =B4-B8 -> -222706845
A12: 은행 계좌 잔액 변동 (참고 — 위 손익 추정치와 별개)
A13: 하나은행: 6,728,340원(25.09.02) → 64,516,597원(26.08.31)
A14: 우리은행: 8,963,200원(25.09.01) → 19,616,417원(26.08.31)
A15: 합산 잔액 증감: +68,441,474원 (증가) — 자세한 설명은 [특이사항] 시트 1번 참고
A17: 참고 (영업손익에 포함 안 됨)
A18: 설비투자(CAPEX) — 레벨링 라인 도입 (호이스트/언코일러/레벨링기계) | B18: =비용_요약!B38 -> 130530450
A19: 매출채권 회수(고객 입금, 현금흐름 참고용) | B19: =비용_요약!C39 -> 746320800
A20: 대표자(남은우) 관련 확인필요 특수항목 (별도표기) | B20: =비용_요약!B53 -> 100816970
A22: 주요 가정 및 확인 필요 사항
A23: 1) 비용은 1년간 실제 계좌 출금액(현금주의) 기준이며, ERP 매출은 그린ERP 작업실적(발생주의) 기준입니다. 시점 불일치로 실제 손익과 차이가 있을 수 있습니다.
A24: 2) 스크랩(고철) 매출은 우리은행 별도계좌(1005-203-068218) 은행입금분(147,824,150원, 확정 사실)과 통장 외 현금 수입(월 400만원, 연 4,800만원, 대표님 말씀 기준 미확인 가정치)을 합산했습니다. [매출_스크랩] 시트 참고.
A25: 3) 은행 계좌 잔액은 오히려 증가(+68,441,474원)했습니다. 이는 보유 단기금융상품 해지(288,307,837원)와 세무환급/정부지원금(47,535,437원)이 영업활동 부족분을 메웠기 때문으로 추정됩니다. [특이사항] 시트 참고.
A26: 4) 대표자(남은우) 관련 확인필요 특수항목(100,816,970원)은 영업비용으로 단정하지 않고 별도표기했습니다. 실제 급여/배당/가지급금 여부는 확인이 필요합니다.
A27: 5) 설비투자(CAPEX, 130,530,450원)는 레벨링 라인(호이스트·언코일러·레벨링기계) 도입 비용으로, 당기 비용이 아닌 자산 취득으로 처리했습니다.
A28: 6) ERP 매출(673,459,335원)과 은행 매출채권 회수액(746,320,800원)은 72,861,465원 차이가 있어 참고용으로만 활용하시기 바랍니다.
A29: 7) "기타(확인필요)" 항목(총 27,215,210원, 124건)은 적요만으로 계정과목을 특정하기 어려워 별도 확인이 필요합니다.
A30: 8) 본 자료는 세무/회계 결산 자료가 아닌 은행 거래내역과 ERP 데이터를 바탕으로 한 추정 자료이며, 확정 손익은 회계사/세무대리인 확인이 필요합니다. 특히 스크랩 현금 수입은 세무 신고 여부도 함께 확인하시기 바랍니다.

Sheet 매출_ERP
A1: 오성철강 2025.09~2026.08 매출 (그린ERP 작업실적 기준)
A2: Source: Supabase greenp_production (그린ERP 미러), slip_date 2025-09-01~2026-08-31, 조회일 2026-09-01
A4: 월별 매출
A5: 월 | B5: 매출(원)
A6: 25.09 | B6: 47661820
A7: 25.10 | B7: 37903580
A8: 25.11 | B8: 50998845
A9: 25.12 | B9: 57367410
A10: 26.01 | B10: 60827800
A11: 26.02 | B11: 48882650
A12: 26.03 | B12: 66159085
A13: 26.04 | B13: 58653145
A14: 26.05 | B14: 67029165
A15: 26.06 | B15: 65218555
A16: 26.07 | B16: 57686650
A17: 26.08 | B17: 55070630
A18: 합계 | B18: =SUM(B6:B17) -> 673459335
A20: 작업유형별 (연간)
A21: 작업유형 | B21: 금액(원) | C21: 건수 | D21: 비중
A22: SLITING | B22: 390797790 | C22: 2809 | D22: 0.58028417
A23: SLITING2 | B23: 180492290 | C23: 1040 | D23: 0.2680077
A24: LEVELLING | B24: 102169255 | C24: 223 | D24: 0.15170813
A27: 거래처별 (상위 15개사, 연간)
A28: 거래처 | B28: 금액(원) | C28: 건수 | D28: 비중
A29: (주)대한강재 | B29: 405842515 | C29: 2824 | D29: 0.60262364
A30: (주)유창 | B30: 58459420 | C30: 397 | D30: 0.086804677
A31: 대산공업(주) | B31: 37640475 | C31: 40 | D31: 0.055891237
A32: 정현철강(주) | B32: 36846660 | C32: 202 | D32: 0.054712524
A33: (주)미래이엔아이 | B33: 25797350 | C33: 129 | D33: 0.038305728
A34: 에버스틸(주) | B34: 23663290 | C34: 84 | D34: 0.035136925
A35: 강진밴드산업(주) | B35: 18366420 | C35: 82 | D35: 0.027271758
A36: 태경스틸(통합) | B36: 15779050 | C36: 89 | D36: 0.023429848
A37: (주)미래이엔제이 | B37: 5379950 | C37: 26 | D37: 0.0079885298
A38: (주)다믓이엔씨 | B38: 4649300 | C38: 15 | D38: 0.0069036091
A39: (주)삼봉스틸 | B39: 4553310 | C39: 19 | D39: 0.0067610764
A40: 한국철강사 | B40: 3643750 | C40: 15 | D40: 0.0054104974
... A43: (주)대한에스엔디 | B43: 3181150 | C43: 18 | D43: 0.0047235963
A44: 기타 26개사 (음수 3건 포함) | B44: 22871865 | D44: 0.033961761
A45: 합계 | B45: 673459335
A47: 참고: greenp_production에는 미강철강/원석철강/(주)영재철강 명의의 소액 마이너스 항목(외주가공비 정산, 합계 -1,787,550원)이 포함되어 있어 순수 고객 매출과 약간의 차감 조정이 섞여 있습니다.
...

Sheet 매출_스크랩
A1: 오성철강 2025.09~2026.08 스크랩(고철) 매출
A2: Source: 거래내역조회20260901(우리은행 스크랩).xls — 우리은행 별도계좌 1005-203-068218 (그린ERP·주계좌 어디에도 없던 제3의 계좌, 이번에 확인됨)
A4: 월별 스크랩 매출
A5: 월 | B5: 은행입금(실제) | C5: 현금(가정, 월 400만원) | D5: 합계
A6: 25.09 | B6: 13313800 | C6: 4000000 | D6: =B6+C6 -> 17313800
A7: 25.10 | B7: 8028800 | C7: 4000000 | D7: =B7+C7 -> 12028800
A8: 25.11 | B8: 10860500 | C8: 4000000 | D8: =B8+C8 -> 14860500
A9: 25.12 | B9: 10928200 | C9: 4000000 | D9: =B9+C9 -> 14928200
A10: 26.01 | B10: 15884000 | C10: 4000000 | D10: =B10+C10 -> 19884000
A11: 26.02 | B11: 5632000 | C11: 4000000 | D11: =B11+C11 -> 9632000
A12: 26.03 | B12: 9104200 | C12: 4000000 | D12: =B12+C12 -> 13104200
A13: 26.04 | B13: 9492000 | C13: 4000000 | D13: =B13+C13 -> 13492000
A14: 26.05 | B14: 18842900 | C14: 4000000 | D14: =B14+C14 -> 22842900
A15: 26.06 | B15: 14420000 | C15: 4000000 | D15: =B15+C15 -> 18420000
A16: 26.07 | B16: 15342800 | C16: 4000000 | D16: =B16+C16 -> 19342800
A17: 26.08 | B17: 15974950 | C17: 4000000 | D17: =B17+C17 -> 19974950
A18: 합계 | B18: =SUM(B6:B17) -> 147824150 | C18: =SUM(C6:C17) -> 48000000 | D18: =SUM(D6:D17) -> 195824150
A20: ※ 노란 셀(현금 가정)은 실제 장부·계좌 근거가 없는 대표님 말씀 기준 추정치입니다. 은행입금분만 확정 사실입니다.
A22: 은행입금 원본 거래내역 (계좌 1005-203-068218)
A23: 거래일시 | B23: 구분 | C23: 내용 | D23: 입금액
A24: 2025.09.09 20:28 | B24: 부가세 | C24: 감사합니다 | D24: 4687900
A25: 2025.09.10 14:12 | B25: 부가세 | C25: 감사합니다 | D25: 3186300
A26: 2025.09.20 08:43 | B26: 예금결산 | C26: 예금결산이자 | D26: 2658
A27: 2025.09.26 15:26 | B27: 부가세 | C27: 감사합니다 | D27: 5439600
A28: 2025.10.28 10:38 | B28: 부가세 | C28: 감사합니다 | D28: 8028800
A29: 2025.11.18 10:53 | B29: 부가세 | C29: 감사합니다 | D29: 3647000
A30: 2025.11.27 11:10 | B30: 부가세 | C30: 감사합니다 | D30: 3976000
A31: 2025.11.28 15:33 | B31: 부가세 | C31: 감사합니다 | D31: 3237500
A32: 2025.12.09 14:47 | B32: 부가세 | C32: 감사합니다 | D32: 3913000
A33: 2025.12.20 08:12 | B33: 예금결산 | C33: 예금결산이자 | D33: 1560
A34: 2025.12.30 13:49 | B34: 부가세 | C34: 감사합니다 | D34: 3000700
A35: 2025.12.31 09:21 | B35: 부가세 | C35: 감사합니다 | D35: 4014500
... A57: 2026.08.25 08:23 | B57: 부가세 | C57: 감사합니다 | D57: 7100550
C58: 합계 (이자수익 포함) | D58: =SUM(D24:D57) -> 147833521
A60: 참고: 이 계좌에서 자사 주계좌로 이체된 내부이체 합계 119,000,000원(10건)은 매출이 아니며, 주계좌 쪽 비용_거래내역 시트에서 이미 "제외-계좌간 자금이체" 등으로 처리되어 중복 계산되지 않습니다.

Sheet 비용_거래내역
A1: 2025.09.01 ~ 2026.09.01 은행 거래내역 (하나은행 433-910049-16804, 우리은행 1005-404-709760)
A2: Source: 거래내역조회20260901(우리은행내역1변).xls, 거래내역조회_20260901(하나은행1년치).xls. 회색 행=P&L 집계 제외(설비투자·매출채권회수·계좌간이체·투자활동·잡수익·환급), 노란 셀=계정과목 확인 필요, 파란 행=대표자 관련 확인필요 특수항목
A4: 은행 | B4: 거래일시 | C4: 구분 | D4: 내용 | E4: 출금액 | F4: 입금액 | G4: 거래후잔액 | H4: 카테고리
A5: 하나은행 | B5: 2026-08-31 16:03:52 | C5: 타행이체 | D5: (주)유창 | E5: 0 | F5: 4311934 | G5: 64516597 | H5: 제외-매출채권 회수(수금)
A6: 하나은행 | B6: 2026-08-31 15:54:17 | C6: 타행이체 | D6: (주)디엘메탈 | E6: 0 | F6: 192500 | G6: 60204663 | H6: 제외-매출채권 회수(수금)
A7: 하나은행 | B7: 2026-08-31 15:48:00 | C7: 타행송금(기업은행) | D7: 위드환경보건 ((5월누락분)) | E7: 200000 | F7: 0 | G7: 60012163 | H7: 지급수수료-환경측정
A8: 하나은행 | B8: 2026-08-31 15:47:59 | C8: 타행송금(기업은행) | D8: 승원철강 ((철밴딘19m)) | E8: 1265880 | F8: 0 | G8: 60212163 | H8: 외주가공비/자재비
A9: 하나은행 | B9: 2026-08-31 15:47:58 | C9: 타행송금(신한은행) | D9: 최윤애 ((원프드식당)) | E9: 1694550 | F9: 0 | G9: 61478043 | H9: 복리후생비-식대
A10: 하나은행 | B10: 2026-08-31 15:47:57 | C10: 타행송금(우체국) | D10: 윤영기 ((스키드=33)) | E10: 330000 | F10: 0 | G10: 63172593 | H10: 수선비/소모품비
A11: 하나은행 | B11: 2026-08-31 14:13:29 | C11: 타행이체 | D11: (주)주찬스틸 | E11: 0 | F11: 849200 | G11: 63502593 | H11: 제외-매출채권 회수(수금)
A12: 하나은행 | B12: 2026-08-31 14:12:12 | C12: 타행이체 | D12: 주식회사인창 | E12: 0 | F12: 234960 | G12: 62653393 | H12: 제외-매출채권 회수(수금)
A13: 하나은행 | B13: 2026-08-31 13:33:22 | C13: 타행이체 | D13: (주)대한에스엔디 | E13: 0 | F13: 547140 | G13: 62418433 | H13: 제외-매출채권 회수(수금)
A14: 하나은행 | B14: 2026-08-31 10:19:02 | C14: 타행이체 | D14: 대산공업(주) | E14: 0 | F14: 2799170 | G14: 61871293 | H14: 제외-매출채권 회수(수금)
A15: 하나은행 | B15: 2026-08-28 11:22:27 | C15: 타행이체 | D15: (주)미래이엔아이 | E15: 0 | F15: 2669524 | G15: 59072123 | H15: 제외-매출채권 회수(수금)
A16: 하나은행 | B16: 2026-08-27 09:37:46 | C16: 타행송금(신한은행) | D16: 스마트개발비용 | E16: 500000 | F16: 0 | G16: 56402599 | H16: 무형자산-개발비
... A1068: 우리은행 | B1068: 2025.09.01 08:03 | C1068: 타행자동 | D1068: 농협-주식회사한성소 | E1068: 110000 | F1068: 0 | G1068: 8963200 | H1068: 기타(확인필요)

Sheet 비용_요약
A1: 2025.09~2026.08 (1년) 비용 요약 (은행 출금 기준, 카테고리별)
A2: 아래 금액은 비용_거래내역 시트를 SUMIF로 집계한 값입니다. 카테고리 재분류가 필요하면 비용_거래내역의 H열(카테고리)을 수정하면 자동 반영됩니다.
A4: 비용 항목 | B4: 금액(원)
A5: 인건비-급여 | B5: =SUMIF(비용_거래내역!$H$5:$H$1068,A5,비용_거래내역!$E$5:$E$1068) -> 423859400
A6: 이자비용 | B6: =SUMIF(비용_거래내역!$H$5:$H$1068,A6,비용_거래내역!$E$5:$E$1068) -> 88110056
A7: 인건비-4대보험 | B7: =SUMIF(비용_거래내역!$H$5:$H$1068,A7,비용_거래내역!$E$5:$E$1068) -> 73057160
A8: 수도광열비-전기 | B8: =SUMIF(비용_거래내역!$H$5:$H$1068,A8,비용_거래내역!$E$5:$E$1068) -> 64929770
A9: 카드대금 | B9: =SUMIF(비용_거래내역!$H$5:$H$1068,A9,비용_거래내역!$E$5:$E$1068) -> 60680954
A10: 지급수수료-기타용역 | B10: =SUMIF(비용_거래내역!$H$5:$H$1068,A10,비용_거래내역!$E$5:$E$1068) -> 31979346
A11: 세금과공과-부가가치세 | B11: =SUMIF(비용_거래내역!$H$5:$H$1068,A11,비용_거래내역!$E$5:$E$1068) -> 29284630
A12: 외주가공비/자재비 | B12: =SUMIF(비용_거래내역!$H$5:$H$1068,A12,비용_거래내역!$E$5:$E$1068) -> 27783843
A13: 세금과공과 | B13: =SUMIF(비용_거래내역!$H$5:$H$1068,A13,비용_거래내역!$E$5:$E$1068) -> 14013820
A14: 복리후생비-단체보험(추정) | B14: =SUMIF(비용_거래내역!$H$5:$H$1068,A14,비용_거래내역!$E$5:$E$1068) -> 10447200
A15: 인건비-퇴직/연금 | B15: =SUMIF(비용_거래내역!$H$5:$H$1068,A15,비용_거래내역!$E$5:$E$1068) -> 10133730
A16: 수선비/소모품비 | B16: =SUMIF(비용_거래내역!$H$5:$H$1068,A16,비용_거래내역!$E$5:$E$1068) -> 6624596
... A33: 기타(확인필요) | B33: =SUMIF(비용_거래내역!$H$5:$H$1068,A33,비용_거래내역!$E$5:$E$1068) -> 27215210
A34: 영업비용 합계 (대표자 관련 특수항목 제외) | B34: =SUM(B5:B33) -> 896166180
A36: 별도 참고 (영업비용 아님, 위 합계에서 제외됨)
A37: 항목 | B37: 출금액 | C37: 입금액
A38: 설비투자(CAPEX)-비용아님 | B38: =SUMIF(비용_거래내역!$H$5:$H$1068,"설비투자(CAPEX)-비용아님",비용_거래내역!$E$5:$E$1068) -> 130530450 | C38: =SUMIF(비용_거래내역!$H$5:$H$1068,"설비투자(CAPEX)-비용아님",비용_거래내역!$F$5:$F$1068) -> 0
A39: 매출채권 회수(수금, 참고용) | B39: =SUMIF(비용_거래내역!$H$5:$H$1068,"제외-매출채권 회수(수금)",비용_거래내역!$E$5:$E$1068) -> 0 | C39: =SUMIF(비용_거래내역!$H$5:$H$1068,"제외-매출채권 회수(수금)",비용_거래내역!$F$5:$F$1068) -> 746320800
A40: 계좌간 자금이체(참고용) | B40: =SUMIF(비용_거래내역!$H$5:$H$1068,"제외-계좌간 자금이체(남은우 경유)",비용_거래내역!$E$5:$E$1068) -> 405000000 | C40: =SUMIF(비용_거래내역!$H$5:$H$1068,"제외-계좌간 자금이체(남은우 경유)",비용_거래내역!$F$5:$F$1068) -> 400000000
A41: 계좌간 자금이체 2(참고용) | B41: =SUMIF(비용_거래내역!$H$5:$H$1068,"제외-계좌간 자금이체",비용_거래내역!$E$5:$E$1068) -> 0 | C41: =SUMIF(비용_거래내역!$H$5:$H$1068,"제외-계좌간 자금이체",비용_거래내역!$F$5:$F$1068) -> 115000000
A42: 단기금융상품 매도(투자활동) | B42: =SUMIF(비용_거래내역!$H$5:$H$1068,"제외-단기금융상품 매도(투자활동)",비용_거래내역!$E$5:$E$1068) -> 0 | C42: =SUMIF(비용_거래내역!$H$5:$H$1068,"제외-단기금융상품 매도(투자활동)",비용_거래내역!$F$5:$F$1068) -> 251887157
A43: 예금해지(투자활동) | B43: =SUMIF(비용_거래내역!$H$5:$H$1068,"제외-예금해지(투자활동)",비용_거래내역!$E$5:$E$1068) -> 0 | C43: =SUMIF(비용_거래내역!$H$5:$H$1068,"제외-예금해지(투자활동)",비용_거래내역!$F$5:$F$1068) -> 36420680
A44: 잡수익-이자수익 | B44: =SUMIF(비용_거래내역!$H$5:$H$1068,"잡수익-이자수익",비용_거래내역!$E$5:$E$1068) -> 0 | C44: =SUMIF(비용_거래내역!$H$5:$H$1068,"잡수익-이자수익",비용_거래내역!$F$5:$F$1068) -> 54437
A45: 잡수익-정부지원금(고용부) | B45: =SUMIF(비용_거래내역!$H$5:$H$1068,"잡수익-정부지원금(고용부)",비용_거래내역!$E$5:$E$1068) -> 0 | C45: =SUMIF(비용_거래내역!$H$5:$H$1068,"잡수익-정부지원금(고용부)",비용_거래내역!$F$5:$F$1068) -> 4672440
A46: 잡수익-정부지원금(추정) | B46: =SUMIF(비용_거래내역!$H$5:$H$1068,"잡수익-정부지원금(추정)",비용_거래내역!$E$5:$E$1068) -> 0 | C46: =SUMIF(비용_거래내역!$H$5:$H$1068,"잡수익-정부지원금(추정)",비용_거래내역!$F$5:$F$1068) -> 11000000
A47: 환급-세무서(추정) | B47: =SUMIF(비용_거래내역!$H$5:$H$1068,"환급-세무서(추정, P&L 별도표기)",비용_거래내역!$E$5:$E$1068) -> 0 | C47: =SUMIF(비용_거래내역!$H$5:$H$1068,"환급-세무서(추정, P&L 별도표기)",비용_거래내역!$F$5:$F$1068) -> 31808560
A49: 대표자 관련 확인필요 특수항목 (별도표기, 위 영업비용 합계에서 제외)
A50: 대표자 관련 대액 출금 | B50: =SUMIF(비용_거래내역!$H$5:$H$1068,"기타(확인필요)-대표자 관련 대액 출금",비용_거래내역!$E$5:$E$1068) -> 56000000
A51: 대표자 정기적금(추정) | B51: =SUMIF(비용_거래내역!$H$5:$H$1068,"기타(확인필요)-대표자 정기적금(추정)",비용_거래내역!$E$5:$E$1068) -> 24000000
A52: 대표자 관련(용도미상) | B52: =SUMIF(비용_거래내역!$H$5:$H$1068,"기타(확인필요)-대표자 관련(용도미상)",비용_거래내역!$E$5:$E$1068) -> 20816970
A53: 대표자 특수항목 합계 | B53: =SUM(B50:B52) -> 100816970

Sheet 월별추이
A1: 월별 매출 · 영업비용 · 손익 추이 (2025.09 ~ 2026.08)
A2: 매출: 그린ERP(발생주의) + 스크랩 매출(은행입금 실제 + 현금 가정) / 비용: 은행 실제출금(현금주의, 대표자 특수항목 제외) — 노란 열은 미확인 가정치가 포함되어 있습니다.
A4: 월 | B4: ERP매출(원) | C4: 스크랩매출-은행(원) | D4: 스크랩매출-현금가정(원) | E4: 총매출(원) | F4: 영업비용(원) | G4: 손익(원)
A5: 25.09 | B5: 47661820 | C5: 13313800 | D5: 4000000 | E5: =B5+C5+D5 -> 64975620 | F5: 88219750 | G5: =E5-F5 -> -23244130
A6: 25.10 | B6: 37903580 | C6: 8028800 | D6: 4000000 | E6: =B6+C6+D6 -> 49932380 | F6: 86038027 | G6: =E6-F6 -> -36105647
A7: 25.11 | B7: 50998845 | C7: 10860500 | D7: 4000000 | E7: =B7+C7+D7 -> 65859345 | F7: 62229684 | G7: =E7-F7 -> 3629661
A8: 25.12 | B8: 57367410 | C8: 10928200 | D8: 4000000 | E8: =B8+C8+D8 -> 72295610 | F8: 67548210 | G8: =E8-F8 -> 4747400
A9: 26.01 | B9: 60827800 | C9: 15884000 | D9: 4000000 | E9: =B9+C9+D9 -> 80711800 | F9: 70338524 | G9: =E9-F9 -> 10373276
A10: 26.02 | B10: 48882650 | C10: 5632000 | D10: 4000000 | E10: =B10+C10+D10 -> 58514650 | F10: 82584837 | G10: =E10-F10 -> -24070187
A11: 26.03 | B11: 66159085 | C11: 9104200 | D11: 4000000 | E11: =B11+C11+D11 -> 79263285 | F11: 70961860 | G11: =E11-F11 -> 8301425
A12: 26.04 | B12: 58653145 | C12: 9492000 | D12: 4000000 | E12: =B12+C12+D12 -> 72145145 | F12: 63793546 | G12: =E12-F12 -> 8351599
A13: 26.05 | B13: 67029165 | C13: 18842900 | D13: 4000000 | E13: =B13+C13+D13 -> 89872065 | F13: 59745896 | G13: =E13-F13 -> 30126169
A14: 26.06 | B14: 65218555 | C14: 14420000 | D14: 4000000 | E14: =B14+C14+D14 -> 83638555 | F14: 76780449 | G14: =E14-F14 -> 6858106
A15: 26.07 | B15: 57686650 | C15: 15342800 | D15: 4000000 | E15: =B15+C15+D15 -> 77029450 | F15: 94554314 | G15: =E15-F15 -> -17524864
A16: 26.08 | B16: 55070630 | C16: 15974950 | D16: 4000000 | E16: =B16+C16+D16 -> 75045580 | F16: 73371083 | G16: =E16-F16 -> 1674497
A17: 합계 | B17: =SUM(B5:B16) -> 673459335 | C17: =SUM(C5:C16) -> 147824150 | D17: =SUM(D5:D16) -> 48000000 | E17: =SUM(E5:E16) -> 869283485 | F17: =SUM(F5:F16) -> 896166180 | G17: =SUM(G5:G16) -> -26882695
A19: ※ 노란 열(스크랩매출-현금가정)은 실제 장부·계좌 근거가 없는 대표님 말씀 기준 추정치(월 400만원)입니다.

Sheet 특이사항
A1: 1년 실적 관련 특이사항 및 별도표기 항목
A3: 1. 현금 잔액 vs 손익 추정치 — 반드시 함께 읽어야 할 참고사항
A4: 은행 계좌 잔액은 지난 1년간 오히려 증가했습니다: 하나은행 6,728,340원(25.09.02) → 64,516,597원(26.08.31), 우리은행 8,963,200원(25.09.01) → 19,616,417원(26.08.31). 합산 +68,441,474원 증가.
A5: 반면 본 자료의 "매출(ERP 발생주의) - 영업비용(은행 현금주의)" 방식으로 추정한 손익은 약 -222,706,845원(적자)입니다. 이 두 수치는 서로 다른 것을 측정하고 있어 모순이 아닙니다:
A6: - 단기금융상품 매도/예금해지로 유입된 현금 288,307,837원은 매출이 아니라 기존에 회사가 보유하던 투자자산을 현금화한 것입니다 (재무활동 성격).
A7: - 세무서 환급 31,808,560원, 정부지원금 등 잡수익 15,726,877원도 영업활동 매출과는 별개입니다.
A8: - 즉, 회사는 영업활동만으로는 비용을 충당하지 못했고(추정 적자), 보유 투자자산 해지 및 환급/지원금으로 그 부족분을 메우면서 계좌 잔액 자체는 늘어난 것으로 추정됩니다.
A9: - 본 추정에는 대출 원금 증감, 미수금/미지급금 등 재무상태표 항목이 반영되어 있지 않아 정확한 손익은 세무대리인/회계사의 결산 자료로 별도 확인이 필요합니다.
A11: 2. ERP 매출과 은행 매출채권 회수액의 차이
A12: ERP 발생주의 매출 합계: 673,459,335원 / 은행 매출채권 회수(입금) 합계: 746,320,800원 (차이 +72,861,465원)
A13: 결제 시점 차이(작업월과 입금월이 다른 경우) 또는 ERP 미반영 매출 가능성이 있어 참고용으로만 활용하시기 바랍니다.
A15: 3. 설비투자 (CAPEX) — 레벨링 라인 도입, 영업비용에서 제외
A16: 은행 | B16: 거래일 | C16: 내용 | D16: 금액(원)
A17: 우리은행 | B17: 2025-09-08 | C17: 기업호이스트장비대 | D17: 27915450
A18: 우리은행 | B18: 2025-09-08 | C18: 기업금성호이스트 | D18: 5600000
A19: 우리은행 | B19: 2025-11-06 | C19: 기업호이스트레벨러금 | D19: 35976000
A20: 우리은행 | B20: 2025-12-04 | C20: 기업대흥엔지니어링 | D20: 10689000
A21: 우리은행 | B21: 2025-12-31 | C21: 기업대흥엔지니어링 | D21: 7120000
A22: 우리은행 | B22: 2026-01-30 | C22: 기업금성호이스트 | D22: 440000
A23: 하나은행 | B23: 2026-07-06 | C23: 금성호이스트(점검외수리) | D23: 1540000
A24: 하나은행 | B24: 2026-07-20 | C24: 대홍엔지니어링(언코일러선금) | D24: 11770000
A25: 하나은행 | B25: 2026-08-26 | C25: 대홍엔지니어링(레베링기계잔금) | D25: 29480000
C26: 합계 | D26: 130530450
A28: 4. 대표자(남은우) 관련 확인 필요 항목 (합계 100,816,970원)
A29: 56,000,000원 — 2025년 중 "남은우" 단일 거래, 대액 출금 1건. 용도 확인 필요.
A30: 24,000,000원 — "n회-남은우" 형식의 정기적 출금 8건. 대표자 개인 정기적금으로 추정되나 확인 필요.
A31: 20,816,970원 — "남은우" 단독 거래(급여/휴가비 패턴에 해당하지 않는) 4건. 용도 미상.
A32: ※ 위 3개 항목은 급여로 단정하지 않고 별도 확인이 필요한 항목으로 분리 표기했습니다. 회사 비용이 아닌 대표자 개인 자금 이동일 가능성이 있습니다.
A34: 5. 세무서 환급 및 잡수익 (영업외수익, P&L 별도표기)
A35: 세무서 환급 추정 3건, 합계 31,808,560원 (안산세무서 31,036,360원 26.02.10, 시흥세무서 731,970원 26.06.17, 안산세무서 40,230원 26.06.02) — 부가가치세 등 환급으로 추정.
A36: 잡수익-이자수익 54,437원 / 잡수익-정부지원금(고용부) 4,672,440원 / 잡수익-정부지원금(추정, 경기경제과학/경기테크노파크) 11,000,000원.
A38: 6. 거래처 집중도
A39: 상위 8개사(태경스틸 통합 기준)가 연간 매출의 약 96.6%를 차지하며, 그중 (주)대한강재 1개사가 60.3%(405,842,515원)로 절대적 비중을 차지합니다.
A40: 이는 8월 단월 기준(57.8%)보다도 높은 수치로, 연간으로 보면 특정 거래처 의존도가 더욱 뚜렷합니다.
A42: 7. 기타(확인필요) 일반 항목
... A49: 이 계좌에서 자사 주계좌로 이체된 내부이체(합계 119,000,000원)는 이미 주계좌 쪽에서 "계좌간 자금이체"로 제외 처리되어 있어 중복 계산되지 않았습니다. 상세 내역은 [매출_스크랩] 시트 참고.
